<?xml version="1.0"?>
<!--
Copyright (c) 2018, STEREOLABS.

All rights reserved.

THIS SOFTWARE IS PROVIDED BY THE COPYRIGHT HOLDERS AND CONTRIBUTORS
"AS IS" AND ANY EXPRESS OR IMPLIED WARRANTIES, INCLUDING, BUT NOT
LIMITED TO, THE IMPLIED WARRANTIES OF MERCHANTABILITY AND FITNESS FOR
A PARTICULAR PURPOSE ARE DISCLAIMED. IN NO EVENT SHALL THE COPYRIGHT
OWNER OR CONTRIBUTORS BE LIABLE FOR ANY DIRECT, INDIRECT, INCIDENTAL,
SPECIAL, EXEMPLARY, OR CONSEQUENTIAL DAMAGES (INCLUDING, BUT NOT
LIMITED TO, PROCUREMENT OF SUBSTITUTE GOODS OR SERVICES; LOSS OF USE,
DATA, OR PROFITS; OR BUSINESS INTERRUPTION) HOWEVER CAUSED AND ON ANY
THEORY OF LIABILITY, WHETHER IN CONTRACT, STRICT LIABILITY, OR TORT
(INCLUDING NEGLIGENCE OR OTHERWISE) ARISING IN ANY WAY OUT OF THE USE
OF THIS SOFTWARE, EVEN IF ADVISED OF THE POSSIBILITY OF SUCH DAMAGE.
-->
<robot name="zedm_camera_2">

<!-- fcu  -->
    <link name="base_link_2" />

<!-- Camera Center -->
    <joint name="zed_camera_center_joint_2" type="fixed">
        <parent link="base_link_2"/>
        <child link="zed_camera_center_2"/>
        <origin xyz="0.08 -0.03 0.027" rpy="0 0 0" />
    </joint>

    <link name="zed_camera_center_2">
        <visual>
            <origin xyz="0 0 0" rpy="0 0 0"/>
            <geometry>
                <mesh filename="package://zed_wrapper/urdf/models/ZEDM.stl" />
            </geometry>
            <material name="light_grey">
                <color rgba="0 0 0 0.9"/>
            </material>
        </visual>
    </link>

<!-- Left Camera -->
    <joint name="zed_left_camera_joint_2" type="fixed">
        <parent link="zed_camera_center_2"/>
        <child link="zed_left_camera_frame_2"/>
        <origin xyz="0 0.03 0" rpy="0 0 0" />
    </joint>

    <link name="zed_left_camera_frame_2" />

    <joint name="zed_left_camera_optical_joint_2" type="fixed">
        <origin xyz="0 0 0" rpy="-1.57079632679 0.0 -1.57079632679"/>
        <parent link="zed_left_camera_frame_2"/>
        <child link="zed_left_camera_optical_frame_2"/>
    </joint>

    <link name="zed_left_camera_optical_frame_2"/>

<!-- Right Camera -->
    <joint name="zed_right_camera_joint_2" type="fixed">
        <parent link="zed_camera_center_2"/>
        <child link="zed_right_camera_frame_2"/>
        <origin xyz="0 -0.03 0" rpy="0 0 0" />
    </joint>

    <link name="zed_right_camera_frame_2" />

    <joint name="zed_right_camera_optical_joint_2" type="fixed">
        <origin xyz="0 0 0" rpy="-1.57079632679 0.0 -1.57079632679"/>
        <parent link="zed_right_camera_frame_2"/>
        <child link="zed_right_camera_optical_frame_2"/>
    </joint>

    <link name="zed_right_camera_optical_frame_2"/>

<!-- IMU -->    
    <joint name="imu_link_joint_2" type="floating">
        <parent link="zed_camera_center_2"/>
        <child link="zed_imu_link_2"/>
        <origin xyz="0 0 0" rpy="0 0 0" />
    </joint>
    <link name="zed_imu_link_2" />
 
</robot>
